Workbook

Sheet Brief
A1: Workforce Management System Implementation - Business Analyst portfolio project
A2: Self-directed project modelled on a BA role supporting a WFM / Field Service / time & attendance rollout. All data is synthetic.
A4: Scenario | B4: Fictional environmental services company moving ~2,300 staff in Australia and New Zealand from paper timesheets and legacy HR onto a new Workforce Management and Field Service system.
A5: Your role | B5: Business Analyst reporting to the Head of Transformation: requirements, process mapping, configuration, data migration, UAT, training and go-live support.
A6: How to read it | B6: Start at Dashboard. Then Requirements -> Process_Map -> Config -> Validation -> Recon -> UAT -> GoLive_Training. Resume_Uplift maps each gap to a bullet.
A7: Key finding | B7: Migration accuracy is well below go-live standard; defects trace back to source data issues and load mappings. See Validation and Recon.
A8: Skills demonstrated | B8: Requirements gathering, process mapping, system configuration, data migration, validation, reconciliation, INDEX/MATCH, pivot-style reporting, UAT, training materials, stakeholder engagement.
A9: Assumptions | B9: All people, award codes, rates and UAT results are fictional/simulated. Blue font = editable inputs. Replace or extend with your own data.
A10: Stretch tasks | B10: 1) Build a real PivotTable on Recon. 2) Add a Python/pandas script that reproduces Recon. 3) Draw the process map in Lucidchart. 4) Write a one-page go/no-go memo from the Dashboard numbers.

Sheet Dashboard
A1: Dashboard - migration health, test results and requirements coverage
A2: All figures are live formulas.
A4: Data migration | D4: Region | E4: Legacy | F4: Match | G4: Mismatch | H4: Missing | I4: Accuracy
A5: Legacy records | B5: =COUNTA(Legacy_Employees!A5:A66) -> 62 | D5: NSW | E5: =COUNTIF(Recon!$B$5:$B$66,D5) -> 14 | F5: =COUNTIFS(Recon!$B$5:$B$66,$D5,Recon!$H$5:$H$66,"Match") -> 9 | G5: =COUNTIFS(Recon!$B$5:$B$66,$D5,Recon!$H$5:$H$66,"Mismatch") -> 4 | H5: =COUNTIFS(Recon!$B$5:$B$66,$D5,Recon!$H$5:$H$66,"Missing") -> 1 | I5: =IF(E5=0,0,F5/E5) -> 0.64285714
A6: Records in WFM | B6: =COUNTA(WFM_Import!A5:A63) -> 59 | D6: VIC | E6: =COUNTIF(Recon!$B$5:$B$66,D6) -> 17 | F6: =COUNTIFS(Recon!$B$5:$B$66,$D6,Recon!$H$5:$H$66,"Match") -> 12 | G6: =COUNTIFS(Recon!$B$5:$B$66,$D6,Recon!$H$5:$H$66,"Mismatch") -> 2 | H6: =COUNTIFS(Recon!$B$5:$B$66,$D6,Recon!$H$5:$H$66,"Missing") -> 3 | I6: =IF(E6=0,0,F6/E6) -> 0.70588235
A7: Match | B7: =COUNTIF(Recon!H5:H66,"Match") -> 48 | D7: QLD | E7: =COUNTIF(Recon!$B$5:$B$66,D7) -> 16 | F7: =COUNTIFS(Recon!$B$5:$B$66,$D7,Recon!$H$5:$H$66,"Match") -> 14 | G7: =COUNTIFS(Recon!$B$5:$B$66,$D7,Recon!$H$5:$H$66,"Mismatch") -> 2 | H7: =COUNTIFS(Recon!$B$5:$B$66,$D7,Recon!$H$5:$H$66,"Missing") -> 0 | I7: =IF(E7=0,0,F7/E7) -> 0.875
A8: Field mismatches | B8: =COUNTIF(Recon!H5:H66,"Mismatch") -> 10 | D8: NZ | E8: =COUNTIF(Recon!$B$5:$B$66,D8) -> 15 | F8: =COUNTIFS(Recon!$B$5:$B$66,$D8,Recon!$H$5:$H$66,"Match") -> 13 | G8: =COUNTIFS(Recon!$B$5:$B$66,$D8,Recon!$H$5:$H$66,"Mismatch") -> 2 | H8: =COUNTIFS(Recon!$B$5:$B$66,$D8,Recon!$H$5:$H$66,"Missing") -> 0 | I8: =IF(E8=0,0,F8/E8) -> 0.86666667
A9: Missing in WFM | B9: =COUNTIF(Recon!H5:H66,"Missing") -> 4 | D9: Total | E9: =SUM(E5:E8) -> 62 | F9: =SUM(F5:F8) -> 48 | G9: =SUM(G5:G8) -> 10 | H9: =SUM(H5:H8) -> 4 | I9: =IF(E9=0,0,F9/E9) -> 0.77419355
A10: Orphans in WFM (not in legacy) | B10: =COUNTIF(WFM_Import!I5:I63,"Orphan") -> 3
A11: Migration accuracy (Match / Legacy) | B11: =IF(B5=0,0,B7/B5) -> 0.77419355 | D11: Note: pivot-style table via COUNTIFS. Extension task: build a real PivotTable on Recon (Insert > PivotTable).
A13: Pre-migration data quality
A14: Records failing validation | B14: =COUNTIF(Validation!G5:G66,"Fail") -> 12
A15: Duplicate IDs | B15: =COUNTIF(Validation!B5:B66,"Duplicate") -> 4
A16: Missing/invalid emails | B16: =COUNTIF(Validation!C5:C66,"Missing/invalid") -> 3
A17: Invalid award codes | B17: =COUNTIF(Validation!D5:D66,"Invalid code") -> 2
A18: Rates out of range | B18: =COUNTIF(Validation!E5:E66,"Out of range") -> 2
A19: Invalid start dates | B19: =COUNTIF(Validation!F5:F66,"Check date") -> 1
A21: UAT
A22: Total test cases | B22: =COUNTA(UAT!A5:A40) -> 17
A23: Pass | B23: =COUNTIF(UAT!F5:F40,"Pass") -> 11
A24: Fail | B24: =COUNTIF(UAT!F5:F40,"Fail") -> 3
A25: Blocked | B25: =COUNTIF(UAT!F5:F40,"Blocked") -> 1
A26: Not Run | B26: =COUNTIF(UAT!F5:F40,"Not Run") -> 2
A27: Pass rate | B27: =IF(B22=0,0,B23/B22) -> 0.64705882
A29: Requirements
A30: Total requirements | B30: =COUNTA(Requirements!A5:A19) -> 15
A31: Must-haves | B31: =COUNTIF(Requirements!E5:E19,"Must") -> 10
A32: Coverage gaps | B32: =COUNTIF(Requirements!H5:H19,"GAP") -> 0

Sheet Requirements
A1: Requirements - traceability matrix (RTM)
A2: Priority = MoSCoW. 'UAT cases' and 'Coverage' are formulas against the UAT sheet.
A4: ID | B4: Requirement | C4: Type | D4: Stakeholder | E4: Priority | F4: Process area | G4: UAT cases | H4: Coverage | I4: Status
A5: R01 | B5: Employees clock in/out on mobile with GPS location capture | C5: Functional | D5: Field Ops Manager | E5: Must | F5: Time & attendance | G5: =COUNTIF(UAT!$B$5:$B$40,A5) -> 2 | H5: =IF(C5="Training","Via training plan",IF(G5>0,"Covered","GAP")) -> Covered | I5: Approved
A6: R02 | B6: Rosters built per depot with skills/qualification matching | C6: Functional | D6: Depot Team Leaders | E6: Must | F6: Rostering | G6: =COUNTIF(UAT!$B$5:$B$40,A6) -> 1 | H6: =IF(C6="Training","Via training plan",IF(G6>0,"Covered","GAP")) -> Covered | I6: Approved
A7: R03 | B7: System applies overtime and penalty rates per award code | C7: Functional | D7: Payroll Manager | E7: Must | F7: Pay rules | G7: =COUNTIF(UAT!$B$5:$B$40,A7) -> 2 | H7: =IF(C7="Training","Via training plan",IF(G7>0,"Covered","GAP")) -> Covered | I7: Approved
A8: R04 | B8: Leave requests submitted and approved in-system | C8: Functional | D8: HR | E8: Should | F8: Leave | G8: =COUNTIF(UAT!$B$5:$B$40,A8) -> 1 | H8: =IF(C8="Training","Via training plan",IF(G8>0,"Covered","GAP")) -> Covered | I8: Approved
A9: R05 | B9: Field jobs scheduled and dispatched to nearest qualified crew | C9: Functional | D9: Field Ops Manager | E9: Must | F9: Field service | G9: =COUNTIF(UAT!$B$5:$B$40,A9) -> 2 | H9: =IF(C9="Training","Via training plan",IF(G9>0,"Covered","GAP")) -> Covered | I9: Approved
A10: R06 | B10: Employee master data migrated from legacy HR with zero critical defects | C10: Data | D10: Head of Transformation | E10: Must | F10: Data migration | G10: =COUNTIF(UAT!$B$5:$B$40,A10) -> 2 | H10: =IF(C10="Training","Via training plan",IF(G10>0,"Covered","GAP")) -> Covered | I10: Approved
A11: R07 | B11: Team leaders approve timesheets before payroll cut-off | C11: Functional | D11: Payroll Manager | E11: Must | F11: Time & attendance | G11: =COUNTIF(UAT!$B$5:$B$40,A11) -> 1 | H11: =IF(C11="Training","Via training plan",IF(G11>0,"Covered","GAP")) -> Covered | I11: Approved
A12: R08 | B12: Approved hours exported to payroll in agreed file format | C12: Integration | D12: Payroll Manager | E12: Must | F12: Integration | G12: =COUNTIF(UAT!$B$5:$B$40,A12) -> 1 | H12: =IF(C12="Training","Via training plan",IF(G12>0,"Covered","GAP")) -> Covered | I12: Approved
A13: R09 | B13: NZ employees follow separate public holiday and pay rules | C13: Functional | D13: NZ Operations Lead | E13: Must | F13: Pay rules | G13: =COUNTIF(UAT!$B$5:$B$40,A13) -> 1 | H13: =IF(C13="Training","Via training plan",IF(G13>0,"Covered","GAP")) -> Covered | I13: Approved
A14: R10 | B14: Weekly labour cost report by region and role | C14: Reporting | D14: Finance | E14: Should | F14: Reporting | G14: =COUNTIF(UAT!$B$5:$B$40,A14) -> 1 | H14: =IF(C14="Training","Via training plan",IF(G14>0,"Covered","GAP")) -> Covered | I14: Approved
A15: R11 | B15: Role-based access (employee, team leader, admin) | C15: Non-functional | D15: IT Security | E15: Must | F15: Security | G15: =COUNTIF(UAT!$B$5:$B$40,A15) -> 1 | H15: =IF(C15="Training","Via training plan",IF(G15>0,"Covered","GAP")) -> Covered | I15: Approved
A16: R12 | B16: Audit trail on every timesheet edit | C16: Non-functional | D16: Internal Audit | E16: Should | F16: Compliance | G16: =COUNTIF(UAT!$B$5:$B$40,A16) -> 1 | H16: =IF(C16="Training","Via training plan",IF(G16>0,"Covered","GAP")) -> Covered | I16: Approved
... A19: R15 | B19: Four weeks of hypercare support post go-live | C19: Training | D19: Head of Transformation | E19: Should | F19: Adoption | G19: =COUNTIF(UAT!$B$5:$B$40,A19) -> 0 | H19: =IF(C19="Training","Via training plan",IF(G19>0,"Covered","GAP")) -> Via training plan | I19: Approved

Sheet Process_Map
A1: Process_Map - Timesheet to pay: current vs future state
A2: Text-based process map (swap in a Visio/Lucidchart diagram if you want to extend it).
A4: Step | B4: Current state (as-is) | C4: Pain point | D4: Future state (to-be) | E4: System | F4: Owner | G4: Req ID
A5: 1 | B5: Employee writes hours on paper timesheet | C5: Illegible, late, lost sheets | D5: Employee clocks in/out on mobile app | E5: WFM mobile | F5: Employee | G5: R01
A6: 2 | B6: Team leader collects sheets and emails to admin | C6: 2-3 day delay | D6: Hours flow to team leader approval queue automatically | E6: WFM | F6: System | G6: R07
A7: 3 | B7: Admin re-keys hours into spreadsheet | C7: Re-keying errors, ~5% rework | D7: No re-keying: single source of truth | E7: WFM | F7: System | G7: R07
A8: 4 | B8: Payroll applies overtime rules by hand | C8: Inconsistent rule application | D8: Award rules applied by configured rule engine | E8: WFM config | F8: Payroll | G8: R03
A9: 5 | B9: Exceptions chased by phone | C9: No audit trail | D9: Exception dashboard with audit trail on edits | E9: WFM | F9: Team Leader | G9: R12
A10: 6 | B10: Payroll manager prepares upload file | C10: Manual, error-prone | D10: Automated export in payroll file format | E10: Integration | F10: Payroll | G10: R08
A11: 7 | B11: Finance builds labour cost report in Excel | C11: Report 5+ days after period end | D11: Weekly report by region and role | E11: WFM reporting | F11: Finance | G11: R10

Sheet Config
A1: Config - system configuration baseline
A2: Blue = editable input. All award codes and rates are FICTIONAL (not a real industrial award).
A4: Award code | B4: Description | C4: Base rate ($/hr) | D4: OT multiplier | E4: Weekend multiplier | F4: Min engagement (hrs) | H4: Setting | I4: Value
A5: FS-L1 | B5: Field Services Level 1 (Cleaner) | C5: 32 | D5: 1.5 | E5: 1.5 | F5: 3 | H5: Min valid hourly rate ($) | I5: 25
A6: FS-L2 | B6: Field Services Level 2 (Driver/Helper) | C6: 36 | D6: 1.5 | E6: 1.5 | F6: 3 | H6: Max valid hourly rate ($) | I6: 70
A7: FS-L3 | B7: Field Services Level 3 (Technician) | C7: 41 | D7: 1.5 | E7: 1.5 | F7: 3 | H7: Ordinary hours cap per shift | I7: 7.6
A8: TL-L4 | B8: Team Leader Level 4 | C8: 48 | D8: 1.5 | E8: 1.75 | F8: 4 | H8: Data extract date | I8: 46296
A9: ADM-L2 | B9: Depot Admin Level 2 | C9: 34 | D9: 2 | E9: 1.5 | F9: 4
A12: Worked example: overtime pay rule (use to test configuration logic)
A13: Award code | B13: FS-L2
A14: Hours worked in shift | B14: 10.5
A15: Ordinary hours | B15: =MIN(B14,$I$7) -> 7.6
A16: Overtime hours | B16: =MAX(0,B14-$I$7) -> 2.9
A17: Base rate | B17: =INDEX($C$5:$C$9,MATCH(B13,$A$5:$A$9,0)) -> 36
A18: OT multiplier | B18: =INDEX($D$5:$D$9,MATCH(B13,$A$5:$A$9,0)) -> 1.5
A19: Gross pay ($) | B19: =B15*B17+B16*B17*B18 -> 430.2
A21: Assumption: 7.6 ordinary hours/shift and OT multipliers are illustrative, set to mimic typical award logic.

Sheet Legacy_Employees
A1: Legacy_Employees - source extract (synthetic)
A2: Legacy HR/payroll extract. Contains deliberately seeded data quality defects for the validation exercise.
A4: Employee ID | B4: Name | C4: Region | D4: Role | E4: Award code | F4: Start date | G4: Hourly rate ($) | H4: Email
A5: E1001 | B5: Oscar Hall | C5: VIC | D5: Driver | E5: FS-L2 | F5: 42202 | G5: 36 | H5: oscar.hall@example.com
A6: E1002 | B6: Ruby Green | C6: NSW | D6: Cleaner | E6: FS-L1 | F6: 42242 | G6: 32 | H6: ruby.green@example.com
A7: E1003 | B7: Olivia Patel | C7: VIC | D7: Team Leader | E7: TL-L4 | F7: 43781 | G7: 48 | H7: olivia.patel@example.com
A8: E1004 | B8: Noah Scott | C8: VIC | D8: Driver | E8: FS-L2 | F8: 43743 | G8: 36 | H8: noah.scott@example.com
A9: E1005 | B9: Chloe Hall | C9: NSW | D9: Cleaner | E9: FS-L1 | F9: 44574 | G9: 32
A10: E1006 | B10: Max Green | C10: NSW | D10: Field Technician | E10: FS-L3 | F10: 43629 | G10: 41 | H10: max.green@example.com
A11: E1007 | B11: Olivia Scott | C11: VIC | D11: Cleaner | E11: FS-L1 | F11: 42550 | G11: 32 | H11: olivia.scott@example.com
A12: E1008 | B12: Ella Brown | C12: VIC | D12: Driver | E12: FS-L2 | F12: 44343 | G12: 36 | H12: ella.brown@example.com
A13: E1009 | B13: Ava Green | C13: VIC | D13: Driver | E13: FS-L2 | F13: 44344 | G13: 36 | H13: ava.green@example.com
A14: E1010 | B14: Ava Scott | C14: QLD | D14: Field Technician | E14: FS-L9 | F14: 44921 | G14: 41 | H14: ava.scott@example.com
A15: E1011 | B15: Sophie Singh | C15: NSW | D15: Cleaner | E15: FS-L1 | F15: 44038 | G15: 32 | H15: sophie.singh@example.com
A16: E1012 | B16: Tane Anderson | C16: NZ | D16: Field Technician | E16: FS-L3 | F16: 43912 | G16: 41 | H16: tane.anderson@example.com
A17: E1013 | B17: Ruby Ng | C17: NZ | D17: Field Technician | E17: FS-L3 | F17: 43022 | G17: 0 | H17: ruby.ng@example.com
A18: E1014 | B18: Noah Green | C18: VIC | D18: Field Technician | E18: FS-L3 | F18: 43234 | G18: 41 | H18: noah.green@example.com
A19: E1015 | B19: Aroha Young | C19: QLD | D19: Driver | E19: FS-L2 | F19: 43184 | G19: 36 | H19: aroha.young@example.com
A20: E1016 | B20: Ava Wright | C20: NSW | D20: Field Technician | E20: FS-L3 | F20: 43717 | G20: 41 | H20: ava.wright@example.com
A21: E1017 | B21: Ethan King | C21: QLD | D21: Cleaner | E21: FS-L1 | F21: 43732 | G21: 32 | H21: ethan.king@example.com
A22: E1018 | B22: Tane Scott | C22: NSW | D22: Cleaner | E22: FS-L1 | F22: 44352 | G22: 32
A23: E1019 | B23: Jack Ward | C23: QLD | D23: Field Technician | E23: FS-L3 | F23: 43439 | G23: 41 | H23: jack.ward@example.com
A24: E1020 | B24: Noah Parker | C24: NZ | D24: Field Technician | E24: FS-L3 | F24: 42388 | G24: 41 | H24: noah.parker@example.com
A25: E1021 | B25: Wiremu Lee | C25: NZ | D25: Depot Admin | E25: ADM-L2 | F25: 42271 | G25: 34 | H25: wiremu.lee@example.com
A26: E1022 | B26: Arjun Green | C26: QLD | D26: Cleaner | E26: FS-L1 | F26: 44795 | G26: 32 | H26: arjun.green@example.com
A27: E1023 | B27: Wiremu Harris | C27: QLD | D27: Field Technician | E27: FS-L3 | F27: 44743 | G27: 41 | H27: wiremu.harris@example.com
A28: E1024 | B28: Ruby Taylor | C28: NZ | D28: Driver | E28: FS-L2 | F28: 44507 | G28: 36 | H28: ruby.taylor@example.com
A29: E1025 | B29: Lucas Turner | C29: NSW | D29: Cleaner | E29: FS-L1 | F29: 43182 | G29: 32 | H29: lucas.turner@example.com
A30: E1026 | B30: Oscar Harris | C30: VIC | D30: Cleaner | E30: FS-L1 | F30: 44038 | G30: 32 | H30: oscar.harris@example.com
A31: E1027 | B31: Oscar Scott | C31: NZ | D31: Cleaner | E31: FS-L1 | F31: 43143 | G31: 32 | H31: oscar.scott@example.com
A32: E1028 | B32: Hannah Scott | C32: NZ | D32: Team Leader | E32: TL-L4 | F32: 46460 | G32: 48 | H32: hannah.scott@example.com
A33: E1029 | B33: Priya Harris | C33: QLD | D33: Field Technician | E33: FS-L3 | F33: 42950 | G33: 41 | H33: priya.harris@example.com
A34: E1030 | B34: Ethan Kelly | C34: VIC | D34: Cleaner | E34: FS-L1 | F34: 44702 | G34: 32 | H34: ethan.kelly@example.com
... A37: E1033 | B37: Ethan Ward | C37: QLD | D37: Driver | E37: FS-L2 | F37: 44116 | G37: 36 | H37: ethan.ward@example.com
A38: E1034 | B38: Leo Murphy | C38: NSW | D38: Depot Admin | E38: ADM-L2 | F38: 45199 | G38: 34
A39: E1035 | B39: Oscar Harris | C39: NZ | D39: Depot Admin | E39: ADM-L2 | F39: 43619 | G39: 34 | H39: oscar.harris@example.com
A40: E1036 | B40: Olivia Singh | C40: NZ | D40: Cleaner | E40: FS-L1 | F40: 42280 | G40: 32 | H40: olivia.singh@example.com
A41: E1037 | B41: Mia Brown | C41: NZ | D41: Depot Admin | E41: ADM-L2 | F41: 43397 | G41: 34 | H41: mia.brown@example.com
A42: E1038 | B42: Liam Green | C42: NSW | D42: Field Technician | E42: FS-L3 | F42: 42624 | G42: 41 | H42: liam.green@example.com
A43: E1039 | B43: Sophie Nguyen | C43: QLD | D43: Driver | E43: FS-L2 | F43: 42293 | G43: 36 | H43: sophie.nguyen@example.com
...

Sheet WFM_Import
A1: WFM_Import - what actually landed in the new system (synthetic)
A2: Post-load extract from the new Workforce Management system, with migration defects for reconciliation.
A4: Employee ID | B4: Name | C4: Region | D4: Role | E4: Award code | F4: Start date | G4: Hourly rate ($) | H4: Email | I4: Orphan check (in WFM, not in legacy?)
A5: E1001 | B5: Oscar Hall | C5: VIC | D5: Driver | E5: FS-L2 | F5: 42202 | G5: 36 | H5: oscar.hall@example.com | I5: =IF(COUNTIF(Legacy_Employees!$A$5:$A$66,A5)=0,"Orphan","OK") -> OK
A6: E1002 | B6: Ruby Green | C6: NSW | D6: Cleaner | E6: FS-L1 | F6: 42242 | G6: 32 | H6: ruby.green@example.com | I6: =IF(COUNTIF(Legacy_Employees!$A$5:$A$66,A6)=0,"Orphan","OK") -> OK
A7: E1004 | B7: Noah Scott | C7: VIC | D7: Driver | E7: FS-L2 | F7: 43743 | G7: 36 | H7: noah.scott@example.com | I7: =IF(COUNTIF(Legacy_Employees!$A$5:$A$66,A7)=0,"Orphan","OK") -> OK
A8: E1005 | B8: Chloe Hall | C8: NSW | D8: Cleaner | E8: FS-L1 | F8: 44574 | G8: 32 | I8: =IF(COUNTIF(Legacy_Employees!$A$5:$A$66,A8)=0,"Orphan","OK") -> OK
A9: E1006 | B9: Max Green | C9: NSW | D9: Field Technician | E9: FS-L3 | F9: 43629 | G9: 45.1 | H9: max.green@example.com | I9: =IF(COUNTIF(Legacy_Employees!$A$5:$A$66,A9)=0,"Orphan","OK") -> OK
A10: E1007 | B10: Olivia Scott | C10: VIC | D10: Cleaner | E10: FS-L1 | F10: 42550 | G10: 32 | H10: olivia.scott@example.com | I10: =IF(COUNTIF(Legacy_Employees!$A$5:$A$66,A10)=0,"Orphan","OK") -> OK
A11: E1008 | B11: Ella Brown | C11: VIC | D11: Driver | E11: FS-L2 | F11: 44343 | G11: 36 | H11: ella.brown@example.com | I11: =IF(COUNTIF(Legacy_Employees!$A$5:$A$66,A11)=0,"Orphan","OK") -> OK
A12: E1009 | B12: Ava Green | C12: VIC | D12: Driver | E12: FS-L1 | F12: 44344 | G12: 36 | H12: ava.green@example.com | I12: =IF(COUNTIF(Legacy_Employees!$A$5:$A$66,A12)=0,"Orphan","OK") -> OK
A13: E1010 | B13: Ava Scott | C13: QLD | D13: Field Technician | E13: FS-L9 | F13: 44921 | G13: 41 | H13: ava.scott@example.com | I13: =IF(COUNTIF(Legacy_Employees!$A$5:$A$66,A13)=0,"Orphan","OK") -> OK
A14: E1011 | B14: Sophie Singh | C14: NSW | D14: Cleaner | E14: FS-L1 | F14: 44038 | G14: 32 | H14: sophie.singh@example.com | I14: =IF(COUNTIF(Legacy_Employees!$A$5:$A$66,A14)=0,"Orphan","OK") -> OK
A15: E1012 | B15: Tane Anderson | C15: NZ | D15: Field Technician | E15: FS-L3 | F15: 43912 | G15: 45.1 | H15: tane.anderson@example.com | I15: =IF(COUNTIF(Legacy_Employees!$A$5:$A$66,A15)=0,"Orphan","OK") -> OK
A16: E1013 | B16: Ruby Ng | C16: NZ | D16: Field Technician | E16: FS-L3 | F16: 43022 | G16: 0 | H16: ruby.ng@example.com | I16: =IF(COUNTIF(Legacy_Employees!$A$5:$A$66,A16)=0,"Orphan","OK") -> OK
A17: E1014 | B17: Noah Green | C17: VIC | D17: Field Technician | E17: FS-L3 | F17: 43234 | G17: 41 | H17: noah.green@example.com | I17: =IF(COUNTIF(Legacy_Employees!$A$5:$A$66,A17)=0,"Orphan","OK") -> OK
A18: E1015 | B18: Aroha Young | C18: QLD | D18: Driver | E18: FS-L2 | F18: 43184 | G18: 36 | H18: aroha.young@example.com | I18: =IF(COUNTIF(Legacy_Employees!$A$5:$A$66,A18)=0,"Orphan","OK") -> OK
A19: E1017 | B19: Ethan King | C19: QLD | D19: Cleaner | E19: FS-L1 | F19: 43732 | G19: 32 | H19: ethan.king@example.com | I19: =IF(COUNTIF(Legacy_Employees!$A$5:$A$66,A19)=0,"Orphan","OK") -> OK
A20: E1018 | B20: Tane Scott | C20: NSW | D20: Cleaner | E20: FS-L1 | F20: 44352 | G20: 32 | I20: =IF(COUNTIF(Legacy_Employees!$A$5:$A$66,A20)=0,"Orphan","OK") -> OK
A21: E1019 | B21: Jack Ward | C21: QLD | D21: Field Technician | E21: FS-L3 | F21: 43439 | G21: 41 | H21: jack.ward@example.com | I21: =IF(COUNTIF(Legacy_Employees!$A$5:$A$66,A21)=0,"Orphan","OK") -> OK
A22: E1020 | B22: Noah Parker | C22: NZ | D22: Field Technician | E22: FS-L2 | F22: 42388 | G22: 41 | H22: noah.parker@example.com | I22: =IF(COUNTIF(Legacy_Employees!$A$5:$A$66,A22)=0,"Orphan","OK") -> OK
A23: E1021 | B23: Wiremu Lee | C23: NZ | D23: Depot Admin | E23: ADM-L2 | F23: 42271 | G23: 34 | H23: wiremu.lee@example.com | I23: =IF(COUNTIF(Legacy_Employees!$A$5:$A$66,A23)=0,"Orphan","OK") -> OK
A24: E1022 | B24: Arjun Green | C24: VIC | D24: Cleaner | E24: FS-L1 | F24: 44795 | G24: 32 | H24: arjun.green@example.com | I24: =IF(COUNTIF(Legacy_Employees!$A$5:$A$66,A24)=0,"Orphan","OK") -> OK
A25: E1023 | B25: Wiremu Harris | C25: QLD | D25: Field Technician | E25: FS-L3 | F25: 44743 | G25: 41 | H25: wiremu.harris@example.com | I25: =IF(COUNTIF(Legacy_Employees!$A$5:$A$66,A25)=0,"Orphan","OK") -> OK
A26: E1024 | B26: Ruby Taylor | C26: NZ | D26: Driver | E26: FS-L2 | F26: 44507 | G26: 36 | H26: ruby.taylor@example.com | I26: =IF(COUNTIF(Legacy_Employees!$A$5:$A$66,A26)=0,"Orphan","OK") -> OK
A27: E1025 | B27: Lucas Turner | C27: NSW | D27: Cleaner | E27: FS-L1 | F27: 43182 | G27: 35.2 | H27: lucas.turner@example.com | I27: =IF(COUNTIF(Legacy_Employees!$A$5:$A$66,A27)=0,"Orphan","OK") -> OK
A28: E1026 | B28: Oscar Harris | C28: VIC | D28: Cleaner | E28: FS-L1 | F28: 44038 | G28: 32 | H28: oscar.harris@example.com | I28: =IF(COUNTIF(Legacy_Employees!$A$5:$A$66,A28)=0,"Orphan","OK") -> OK
A29: E1027 | B29: Oscar Scott | C29: NZ | D29: Cleaner | E29: FS-L1 | F29: 43143 | G29: 32 | H29: oscar.scott@example.com | I29: =IF(COUNTIF(Legacy_Employees!$A$5:$A$66,A29)=0,"Orphan","OK") -> OK
A30: E1028 | B30: Hannah Scott | C30: NZ | D30: Team Leader | E30: TL-L4 | F30: 46460 | G30: 48 | H30: hannah.scott@example.com | I30: =IF(COUNTIF(Legacy_Employees!$A$5:$A$66,A30)=0,"Orphan","OK") -> OK
A31: E1029 | B31: Priya Harris | C31: QLD | D31: Field Technician | E31: FS-L3 | F31: 42950 | G31: 41 | H31: priya.harris@example.com | I31: =IF(COUNTIF(Legacy_Employees!$A$5:$A$66,A31)=0,"Orphan","OK") -> OK
A32: E1031 | B32: Sam Green | C32: NZ | D32: Cleaner | E32: FS-L1 | F32: 42751 | G32: 32 | H32: sam.green@example.com | I32: =IF(COUNTIF(Legacy_Employees!$A$5:$A$66,A32)=0,"Orphan","OK") -> OK
... A34: E1033 | B34: Ethan Ward | C34: QLD | D34: Driver | E34: FS-L2 | F34: 44116 | G34: 36 | H34: ethan.ward@example.com | I34: =IF(COUNTIF(Legacy_Employees!$A$5:$A$66,A34)=0,"Orphan","OK") -> OK
A35: E1034 | B35: Leo Murphy | C35: NSW | D35: Depot Admin | E35: ADM-L2 | F35: 45199 | G35: 34 | I35: =IF(COUNTIF(Legacy_Employees!$A$5:$A$66,A35)=0,"Orphan","OK") -> OK
A36: E1035 | B36: Oscar Harris | C36: NZ | D36: Depot Admin | E36: ADM-L2 | F36: 43619 | G36: 34 | H36: oscar.harris@example.com | I36: =IF(COUNTIF(Legacy_Employees!$A$5:$A$66,A36)=0,"Orphan","OK") -> OK
A37: E1036 | B37: Olivia Singh | C37: NZ | D37: Cleaner | E37: FS-L1 | F37: 42280 | G37: 32 | H37: olivia.singh@example.com | I37: =IF(COUNTIF(Legacy_Employees!$A$5:$A$66,A37)=0,"Orphan","OK") -> OK
A38: E1037 | B38: Mia Brown | C38: NZ | D38: Depot Admin | E38: ADM-L2 | F38: 43397 | G38: 34 | H38: mia.brown@example.com | I38: =IF(COUNTIF(Legacy_Employees!$A$5:$A$66,A38)=0,"Orphan","OK") -> OK
A39: E1038 | B39: Liam Green | C39: NSW | D39: Field Technician | E39: FS-L3 | F39: 42624 | G39: 45.1 | H39: liam.green@example.com | I39: =IF(COUNTIF(Legacy_Employees!$A$5:$A$66,A39)=0,"Orphan","OK") -> OK
A40: E1039 | B40: Sophie Nguyen | C40: QLD | D40: Driver | E40: FS-L2 | F40: 42293 | G40: 36 | H40: sophie.nguyen@example.com | I40: =IF(COUNTIF(Legacy_Employees!$A$5:$A$66,A40)=0,"Orphan","OK") -> OK
A41: E1040 | B41: Ethan Hall | C41: NZ | D41: Team Leader | E41: TL-L4 | F41: 43038 | G41: 48 | H41: ethan.hall@example.com | I41: =IF(COUNTIF(Legacy_Employees!$A$5:$A$66,A41)=0,"Orphan","OK") -> OK
A42: E1041 | B42: Grace Brown | C42: QLD | D42: Depot Admin | E42: ADM-L2 | F42: 42477 | G42: 34 | H42: grace.brown@example.com | I42: =IF(COUNTIF(Legacy_Employees!$A$5:$A$66,A42)=0,"Orphan","OK") -> OK
...

Sheet Validation
A1: Validation - pre-migration data quality rules
A2: Each rule is a formula against Legacy_Employees; thresholds come from Config. Fix source data BEFORE loading.
A4: Employee ID | B4: Duplicate ID | C4: Email present/valid | D4: Award code valid | E4: Rate in range | F4: Start date valid | G4: Overall
A5: =Legacy_Employees!A5 -> E1001 | B5: =IF(COUNTIF(Legacy_Employees!$A$5:$A$66,A5)>1,"Duplicate","OK") -> OK | C5: =IF(OR(Legacy_Employees!H5="",ISERROR(FIND("@",Legacy_Employees!H5))),"Missing/invalid","OK") -> OK | D5: =IF(COUNTIF(Config!$A$5:$A$9,Legacy_Employees!E5)=0,"Invalid code","OK") -> OK | E5: =IF(AND(Legacy_Employees!G5>=Config!$I$5,Legacy_Employees!G5<=Config!$I$6),"OK","Out of range") -> OK | F5: =IF(AND(ISNUMBER(Legacy_Employees!F5),Legacy_Employees!F5<=Config!$I$8),"OK","Check date") -> OK | G5: =IF(COUNTIF(B5:F5,"OK")=5,"Pass","Fail") -> Pass
A6: =Legacy_Employees!A6 -> E1002 | B6: =IF(COUNTIF(Legacy_Employees!$A$5:$A$66,A6)>1,"Duplicate","OK") -> OK | C6: =IF(OR(Legacy_Employees!H6="",ISERROR(FIND("@",Legacy_Employees!H6))),"Missing/invalid","OK") -> OK | D6: =IF(COUNTIF(Config!$A$5:$A$9,Legacy_Employees!E6)=0,"Invalid code","OK") -> OK | E6: =IF(AND(Legacy_Employees!G6>=Config!$I$5,Legacy_Employees!G6<=Config!$I$6),"OK","Out of range") -> OK | F6: =IF(AND(ISNUMBER(Legacy_Employees!F6),Legacy_Employees!F6<=Config!$I$8),"OK","Check date") -> OK | G6: =IF(COUNTIF(B6:F6,"OK")=5,"Pass","Fail") -> Pass
A7: =Legacy_Employees!A7 -> E1003 | B7: =IF(COUNTIF(Legacy_Employees!$A$5:$A$66,A7)>1,"Duplicate","OK") -> OK | C7: =IF(OR(Legacy_Employees!H7="",ISERROR(FIND("@",Legacy_Employees!H7))),"Missing/invalid","OK") -> OK | D7: =IF(COUNTIF(Config!$A$5:$A$9,Legacy_Employees!E7)=0,"Invalid code","OK") -> OK | E7: =IF(AND(Legacy_Employees!G7>=Config!$I$5,Legacy_Employees!G7<=Config!$I$6),"OK","Out of range") -> OK | F7: =IF(AND(ISNUMBER(Legacy_Employees!F7),Legacy_Employees!F7<=Config!$I$8),"OK","Check date") -> OK | G7: =IF(COUNTIF(B7:F7,"OK")=5,"Pass","Fail") -> Pass
A8: =Legacy_Employees!A8 -> E1004 | B8: =IF(COUNTIF(Legacy_Employees!$A$5:$A$66,A8)>1,"Duplicate","OK") -> OK | C8: =IF(OR(Legacy_Employees!H8="",ISERROR(FIND("@",Legacy_Employees!H8))),"Missing/invalid","OK") -> OK | D8: =IF(COUNTIF(Config!$A$5:$A$9,Legacy_Employees!E8)=0,"Invalid code","OK") -> OK | E8: =IF(AND(Legacy_Employees!G8>=Config!$I$5,Legacy_Employees!G8<=Config!$I$6),"OK","Out of range") -> OK | F8: =IF(AND(ISNUMBER(Legacy_Employees!F8),Legacy_Employees!F8<=Config!$I$8),"OK","Check date") -> OK | G8: =IF(COUNTIF(B8:F8,"OK")=5,"Pass","Fail") -> Pass
A9: =Legacy_Employees!A9 -> E1005 | B9: =IF(COUNTIF(Legacy_Employees!$A$5:$A$66,A9)>1,"Duplicate","OK") -> OK | C9: =IF(OR(Legacy_Employees!H9="",ISERROR(FIND("@",Legacy_Employees!H9))),"Missing/invalid","OK") -> Missing/invalid | D9: =IF(COUNTIF(Config!$A$5:$A$9,Legacy_Employees!E9)=0,"Invalid code","OK") -> OK | E9: =IF(AND(Legacy_Employees!G9>=Config!$I$5,Legacy_Employees!G9<=Config!$I$6),"OK","Out of range") -> OK | F9: =IF(AND(ISNUMBER(Legacy_Employees!F9),Legacy_Employees!F9<=Config!$I$8),"OK","Check date") -> OK | G9: =IF(COUNTIF(B9:F9,"OK")=5,"Pass","Fail") -> Fail
A10: =Legacy_Employees!A10 -> E1006 | B10: =IF(COUNTIF(Legacy_Employees!$A$5:$A$66,A10)>1,"Duplicate","OK") -> OK | C10: =IF(OR(Legacy_Employees!H10="",ISERROR(FIND("@",Legacy_Employees!H10))),"Missing/invalid","OK") -> OK | D10: =IF(COUNTIF(Config!$A$5:$A$9,Legacy_Employees!E10)=0,"Invalid code","OK") -> OK | E10: =IF(AND(Legacy_Employees!G10>=Config!$I$5,Legacy_Employees!G10<=Config!$I$6),"OK","Out of range") -> OK | F10: =IF(AND(ISNUMBER(Legacy_Employees!F10),Legacy_Employees!F10<=Config!$I$8),"OK","Check date") -> OK | G10: =IF(COUNTIF(B10:F10,"OK")=5,"Pass","Fail") -> Pass
A11: =Legacy_Employees!A11 -> E1007 | B11: =IF(COUNTIF(Legacy_Employees!$A$5:$A$66,A11)>1,"Duplicate","OK") -> Duplicate | C11: =IF(OR(Legacy_Employees!H11="",ISERROR(FIND("@",Legacy_Employees!H11))),"Missing/invalid","OK") -> OK | D11: =IF(COUNTIF(Config!$A$5:$A$9,Legacy_Employees!E11)=0,"Invalid code","OK") -> OK | E11: =IF(AND(Legacy_Employees!G11>=Config!$I$5,Legacy_Employees!G11<=Config!$I$6),"OK","Out of range") -> OK | F11: =IF(AND(ISNUMBER(Legacy_Employees!F11),Legacy_Employees!F11<=Config!$I$8),"OK","Check date") -> OK | G11: =IF(COUNTIF(B11:F11,"OK")=5,"Pass","Fail") -> Fail
A12: =Legacy_Employees!A12 -> E1008 | B12: =IF(COUNTIF(Legacy_Employees!$A$5:$A$66,A12)>1,"Duplicate","OK") -> OK | C12: =IF(OR(Legacy_Employees!H12="",ISERROR(FIND("@",Legacy_Employees!H12))),"Missing/invalid","OK") -> OK | D12: =IF(COUNTIF(Config!$A$5:$A$9,Legacy_Employees!E12)=0,"Invalid code","OK") -> OK | E12: =IF(AND(Legacy_Employees!G12>=Config!$I$5,Legacy_Employees!G12<=Config!$I$6),"OK","Out of range") -> OK | F12: =IF(AND(ISNUMBER(Legacy_Employees!F12),Legacy_Employees!F12<=Config!$I$8),"OK","Check date") -> OK | G12: =IF(COUNTIF(B12:F12,"OK")=5,"Pass","Fail") -> Pass
A13: =Legacy_Employees!A13 -> E1009 | B13: =IF(COUNTIF(Legacy_Employees!$A$5:$A$66,A13)>1,"Duplicate","OK") -> OK | C13: =IF(OR(Legacy_Employees!H13="",ISERROR(FIND("@",Legacy_Employees!H13))),"Missing/invalid","OK") -> OK | D13: =IF(COUNTIF(Config!$A$5:$A$9,Legacy_Employees!E13)=0,"Invalid code","OK") -> OK | E13: =IF(AND(Legacy_Employees!G13>=Config!$I$5,Legacy_Employees!G13<=Config!$I$6),"OK","Out of range") -> OK | F13: =IF(AND(ISNUMBER(Legacy_Employees!F13),Legacy_Employees!F13<=Config!$I$8),"OK","Check date") -> OK | G13: =IF(COUNTIF(B13:F13,"OK")=5,"Pass","Fail") -> Pass
A14: =Legacy_Employees!A14 -> E1010 | B14: =IF(COUNTIF(Legacy_Employees!$A$5:$A$66,A14)>1,"Duplicate","OK") -> OK | C14: =IF(OR(Legacy_Employees!H14="",ISERROR(FIND("@",Legacy_Employees!H14))),"Missing/invalid","OK") -> OK | D14: =IF(COUNTIF(Config!$A$5:$A$9,Legacy_Employees!E14)=0,"Invalid code","OK") -> Invalid code | E14: =IF(AND(Legacy_Employees!G14>=Config!$I$5,Legacy_Employees!G14<=Config!$I$6),"OK","Out of range") -> OK | F14: =IF(AND(ISNUMBER(Legacy_Employees!F14),Legacy_Employees!F14<=Config!$I$8),"OK","Check date") -> OK | G14: =IF(COUNTIF(B14:F14,"OK")=5,"Pass","Fail") -> Fail
A15: =Legacy_Employees!A15 -> E1011 | B15: =IF(COUNTIF(Legacy_Employees!$A$5:$A$66,A15)>1,"Duplicate","OK") -> OK | C15: =IF(OR(Legacy_Employees!H15="",ISERROR(FIND("@",Legacy_Employees!H15))),"Missing/invalid","OK") -> OK | D15: =IF(COUNTIF(Config!$A$5:$A$9,Legacy_Employees!E15)=0,"Invalid code","OK") -> OK | E15: =IF(AND(Legacy_Employees!G15>=Config!$I$5,Legacy_Employees!G15<=Config!$I$6),"OK","Out of range") -> OK | F15: =IF(AND(ISNUMBER(Legacy_Employees!F15),Legacy_Employees!F15<=Config!$I$8),"OK","Check date") -> OK | G15: =IF(COUNTIF(B15:F15,"OK")=5,"Pass","Fail") -> Pass
A16: =Legacy_Employees!A16 -> E1012 | B16: =IF(COUNTIF(Legacy_Employees!$A$5:$A$66,A16)>1,"Duplicate","OK") -> OK | C16: =IF(OR(Legacy_Employees!H16="",ISERROR(FIND("@",Legacy_Employees!H16))),"Missing/invalid","OK") -> OK | D16: =IF(COUNTIF(Config!$A$5:$A$9,Legacy_Employees!E16)=0,"Invalid code","OK") -> OK | E16: =IF(AND(Legacy_Employees!G16>=Config!$I$5,Legacy_Employees!G16<=Config!$I$6),"OK","Out of range") -> OK | F16: =IF(AND(ISNUMBER(Legacy_Employees!F16),Legacy_Employees!F16<=Config!$I$8),"OK","Check date") -> OK | G16: =IF(COUNTIF(B16:F16,"OK")=5,"Pass","Fail") -> Pass
... A66: =Legacy_Employees!A66 -> E1023 | B66: =IF(COUNTIF(Legacy_Employees!$A$5:$A$66,A66)>1,"Duplicate","OK") -> Duplicate | C66: =IF(OR(Legacy_Employees!H66="",ISERROR(FIND("@",Legacy_Employees!H66))),"Missing/invalid","OK") -> OK | D66: =IF(COUNTIF(Config!$A$5:$A$9,Legacy_Employees!E66)=0,"Invalid code","OK") -> OK | E66: =IF(AND(Legacy_Employees!G66>=Config!$I$5,Legacy_Employees!G66<=Config!$I$6),"OK","Out of range") -> OK | F66: =IF(AND(ISNUMBER(Legacy_Employees!F66),Legacy_Employees!F66<=Config!$I$8),"OK","Check date") -> OK | G66: =IF(COUNTIF(B66:F66,"OK")=5,"Pass","Fail") -> Fail

Sheet Recon
A1: Recon - legacy vs new WFM field-level reconciliation
A2: One row per legacy record. Lookups use INDEX/MATCH on Employee ID into WFM_Import.
A4: Employee ID | B4: Region (legacy) | C4: In WFM? | D4: Rate check | E4: Award check | F4: Region check | G4: Start date check | H4: Overall
A5: =Legacy_Employees!A5 -> E1001 | B5: =Legacy_Employees!C5 -> VIC | C5: =IF(ISNUMBER(MATCH($A5,WFM_Import!$A$5:$A$63,0)),"Yes","No") -> Yes | D5: =IF($C5="No","n/a",IF(ROUND(INDEX(WFM_Import!$G$5:$G$63,MATCH($A5,WFM_Import!$A$5:$A$63,0))-Legacy_Employees!G5,2)=0,"OK","Mismatch")) -> OK | E5: =IF($C5="No","n/a",IF(INDEX(WFM_Import!$E$5:$E$63,MATCH($A5,WFM_Import!$A$5:$A$63,0))=Legacy_Employees!E5,"OK","Mismatch")) -> OK | F5: =IF($C5="No","n/a",IF(INDEX(WFM_Import!$C$5:$C$63,MATCH($A5,WFM_Import!$A$5:$A$63,0))=Legacy_Employees!C5,"OK","Mismatch")) -> OK | G5: =IF($C5="No","n/a",IF(INDEX(WFM_Import!$F$5:$F$63,MATCH($A5,WFM_Import!$A$5:$A$63,0))=Legacy_Employees!F5,"OK","Mismatch")) -> OK | H5: =IF($C5="No","Missing",IF(COUNTIF(D5:G5,"OK")=4,"Match","Mismatch")) -> Match
A6: =Legacy_Employees!A6 -> E1002 | B6: =Legacy_Employees!C6 -> NSW | C6: =IF(ISNUMBER(MATCH($A6,WFM_Import!$A$5:$A$63,0)),"Yes","No") -> Yes | D6: =IF($C6="No","n/a",IF(ROUND(INDEX(WFM_Import!$G$5:$G$63,MATCH($A6,WFM_Import!$A$5:$A$63,0))-Legacy_Employees!G6,2)=0,"OK","Mismatch")) -> OK | E6: =IF($C6="No","n/a",IF(INDEX(WFM_Import!$E$5:$E$63,MATCH($A6,WFM_Import!$A$5:$A$63,0))=Legacy_Employees!E6,"OK","Mismatch")) -> OK | F6: =IF($C6="No","n/a",IF(INDEX(WFM_Import!$C$5:$C$63,MATCH($A6,WFM_Import!$A$5:$A$63,0))=Legacy_Employees!C6,"OK","Mismatch")) -> OK | G6: =IF($C6="No","n/a",IF(INDEX(WFM_Import!$F$5:$F$63,MATCH($A6,WFM_Import!$A$5:$A$63,0))=Legacy_Employees!F6,"OK","Mismatch")) -> OK | H6: =IF($C6="No","Missing",IF(COUNTIF(D6:G6,"OK")=4,"Match","Mismatch")) -> Match
A7: =Legacy_Employees!A7 -> E1003 | B7: =Legacy_Employees!C7 -> VIC | C7: =IF(ISNUMBER(MATCH($A7,WFM_Import!$A$5:$A$63,0)),"Yes","No") -> No | D7: =IF($C7="No","n/a",IF(ROUND(INDEX(WFM_Import!$G$5:$G$63,MATCH($A7,WFM_Import!$A$5:$A$63,0))-Legacy_Employees!G7,2)=0,"OK","Mismatch")) -> n/a | E7: =IF($C7="No","n/a",IF(INDEX(WFM_Import!$E$5:$E$63,MATCH($A7,WFM_Import!$A$5:$A$63,0))=Legacy_Employees!E7,"OK","Mismatch")) -> n/a | F7: =IF($C7="No","n/a",IF(INDEX(WFM_Import!$C$5:$C$63,MATCH($A7,WFM_Import!$A$5:$A$63,0))=Legacy_Employees!C7,"OK","Mismatch")) -> n/a | G7: =IF($C7="No","n/a",IF(INDEX(WFM_Import!$F$5:$F$63,MATCH($A7,WFM_Import!$A$5:$A$63,0))=Legacy_Employees!F7,"OK","Mismatch")) -> n/a | H7: =IF($C7="No","Missing",IF(COUNTIF(D7:G7,"OK")=4,"Match","Mismatch")) -> Missing
A8: =Legacy_Employees!A8 -> E1004 | B8: =Legacy_Employees!C8 -> VIC | C8: =IF(ISNUMBER(MATCH($A8,WFM_Import!$A$5:$A$63,0)),"Yes","No") -> Yes | D8: =IF($C8="No","n/a",IF(ROUND(INDEX(WFM_Import!$G$5:$G$63,MATCH($A8,WFM_Import!$A$5:$A$63,0))-Legacy_Employees!G8,2)=0,"OK","Mismatch")) -> OK | E8: =IF($C8="No","n/a",IF(INDEX(WFM_Import!$E$5:$E$63,MATCH($A8,WFM_Import!$A$5:$A$63,0))=Legacy_Employees!E8,"OK","Mismatch")) -> OK | F8: =IF($C8="No","n/a",IF(INDEX(WFM_Import!$C$5:$C$63,MATCH($A8,WFM_Import!$A$5:$A$63,0))=Legacy_Employees!C8,"OK","Mismatch")) -> OK | G8: =IF($C8="No","n/a",IF(INDEX(WFM_Import!$F$5:$F$63,MATCH($A8,WFM_Import!$A$5:$A$63,0))=Legacy_Employees!F8,"OK","Mismatch")) -> OK | H8: =IF($C8="No","Missing",IF(COUNTIF(D8:G8,"OK")=4,"Match","Mismatch")) -> Match
A9: =Legacy_Employees!A9 -> E1005 | B9: =Legacy_Employees!C9 -> NSW | C9: =IF(ISNUMBER(MATCH($A9,WFM_Import!$A$5:$A$63,0)),"Yes","No") -> Yes | D9: =IF($C9="No","n/a",IF(ROUND(INDEX(WFM_Import!$G$5:$G$63,MATCH($A9,WFM_Import!$A$5:$A$63,0))-Legacy_Employees!G9,2)=0,"OK","Mismatch")) -> OK | E9: =IF($C9="No","n/a",IF(INDEX(WFM_Import!$E$5:$E$63,MATCH($A9,WFM_Import!$A$5:$A$63,0))=Legacy_Employees!E9,"OK","Mismatch")) -> OK | F9: =IF($C9="No","n/a",IF(INDEX(WFM_Import!$C$5:$C$63,MATCH($A9,WFM_Import!$A$5:$A$63,0))=Legacy_Employees!C9,"OK","Mismatch")) -> OK | G9: =IF($C9="No","n/a",IF(INDEX(WFM_Import!$F$5:$F$63,MATCH($A9,WFM_Import!$A$5:$A$63,0))=Legacy_Employees!F9,"OK","Mismatch")) -> OK | H9: =IF($C9="No","Missing",IF(COUNTIF(D9:G9,"OK")=4,"Match","Mismatch")) -> Match
A10: =Legacy_Employees!A10 -> E1006 | B10: =Legacy_Employees!C10 -> NSW | C10: =IF(ISNUMBER(MATCH($A10,WFM_Import!$A$5:$A$63,0)),"Yes","No") -> Yes | D10: =IF($C10="No","n/a",IF(ROUND(INDEX(WFM_Import!$G$5:$G$63,MATCH($A10,WFM_Import!$A$5:$A$63,0))-Legacy_Employees!G10,2)=0,"OK","Mismatch")) -> Mismatch | E10: =IF($C10="No","n/a",IF(INDEX(WFM_Import!$E$5:$E$63,MATCH($A10,WFM_Import!$A$5:$A$63,0))=Legacy_Employees!E10,"OK","Mismatch")) -> OK | F10: =IF($C10="No","n/a",IF(INDEX(WFM_Import!$C$5:$C$63,MATCH($A10,WFM_Import!$A$5:$A$63,0))=Legacy_Employees!C10,"OK","Mismatch")) -> OK | G10: =IF($C10="No","n/a",IF(INDEX(WFM_Import!$F$5:$F$63,MATCH($A10,WFM_Import!$A$5:$A$63,0))=Legacy_Employees!F10,"OK","Mismatch")) -> OK | H10: =IF($C10="No","Missing",IF(COUNTIF(D10:G10,"OK")=4,"Match","Mismatch")) -> Mismatch
A11: =Legacy_Employees!A11 -> E1007 | B11: =Legacy_Employees!C11 -> VIC | C11: =IF(ISNUMBER(MATCH($A11,WFM_Import!$A$5:$A$63,0)),"Yes","No") -> Yes | D11: =IF($C11="No","n/a",IF(ROUND(INDEX(WFM_Import!$G$5:$G$63,MATCH($A11,WFM_Import!$A$5:$A$63,0))-Legacy_Employees!G11,2)=0,"OK","Mismatch")) -> OK | E11: =IF($C11="No","n/a",IF(INDEX(WFM_Import!$E$5:$E$63,MATCH($A11,WFM_Import!$A$5:$A$63,0))=Legacy_Employees!E11,"OK","Mismatch")) -> OK | F11: =IF($C11="No","n/a",IF(INDEX(WFM_Import!$C$5:$C$63,MATCH($A11,WFM_Import!$A$5:$A$63,0))=Legacy_Employees!C11,"OK","Mismatch")) -> OK | G11: =IF($C11="No","n/a",IF(INDEX(WFM_Import!$F$5:$F$63,MATCH($A11,WFM_Import!$A$5:$A$63,0))=Legacy_Employees!F11,"OK","Mismatch")) -> OK | H11: =IF($C11="No","Missing",IF(COUNTIF(D11:G11,"OK")=4,"Match","Mismatch")) -> Match
A12: =Legacy_Employees!A12 -> E1008 | B12: =Legacy_Employees!C12 -> VIC | C12: =IF(ISNUMBER(MATCH($A12,WFM_Import!$A$5:$A$63,0)),"Yes","No") -> Yes | D12: =IF($C12="No","n/a",IF(ROUND(INDEX(WFM_Import!$G$5:$G$63,MATCH($A12,WFM_Import!$A$5:$A$63,0))-Legacy_Employees!G12,2)=0,"OK","Mismatch")) -> OK | E12: =IF($C12="No","n/a",IF(INDEX(WFM_Import!$E$5:$E$63,MATCH($A12,WFM_Import!$A$5:$A$63,0))=Legacy_Employees!E12,"OK","Mismatch")) -> OK | F12: =IF($C12="No","n/a",IF(INDEX(WFM_Import!$C$5:$C$63,MATCH($A12,WFM_Import!$A$5:$A$63,0))=Legacy_Employees!C12,"OK","Mismatch")) -> OK | G12: =IF($C12="No","n/a",IF(INDEX(WFM_Import!$F$5:$F$63,MATCH($A12,WFM_Import!$A$5:$A$63,0))=Legacy_Employees!F12,"OK","Mismatch")) -> OK | H12: =IF($C12="No","Missing",IF(COUNTIF(D12:G12,"OK")=4,"Match","Mismatch")) -> Match
A13: =Legacy_Employees!A13 -> E1009 | B13: =Legacy_Employees!C13 -> VIC | C13: =IF(ISNUMBER(MATCH($A13,WFM_Import!$A$5:$A$63,0)),"Yes","No") -> Yes | D13: =IF($C13="No","n/a",IF(ROUND(INDEX(WFM_Import!$G$5:$G$63,MATCH($A13,WFM_Import!$A$5:$A$63,0))-Legacy_Employees!G13,2)=0,"OK","Mismatch")) -> OK | E13: =IF($C13="No","n/a",IF(INDEX(WFM_Import!$E$5:$E$63,MATCH($A13,WFM_Import!$A$5:$A$63,0))=Legacy_Employees!E13,"OK","Mismatch")) -> Mismatch | F13: =IF($C13="No","n/a",IF(INDEX(WFM_Import!$C$5:$C$63,MATCH($A13,WFM_Import!$A$5:$A$63,0))=Legacy_Employees!C13,"OK","Mismatch")) -> OK | G13: =IF($C13="No","n/a",IF(INDEX(WFM_Import!$F$5:$F$63,MATCH($A13,WFM_Import!$A$5:$A$63,0))=Legacy_Employees!F13,"OK","Mismatch")) -> OK | H13: =IF($C13="No","Missing",IF(COUNTIF(D13:G13,"OK")=4,"Match","Mismatch")) -> Mismatch
A14: =Legacy_Employees!A14 -> E1010 | B14: =Legacy_Employees!C14 -> QLD | C14: =IF(ISNUMBER(MATCH($A14,WFM_Import!$A$5:$A$63,0)),"Yes","No") -> Yes | D14: =IF($C14="No","n/a",IF(ROUND(INDEX(WFM_Import!$G$5:$G$63,MATCH($A14,WFM_Import!$A$5:$A$63,0))-Legacy_Employees!G14,2)=0,"OK","Mismatch")) -> OK | E14: =IF($C14="No","n/a",IF(INDEX(WFM_Import!$E$5:$E$63,MATCH($A14,WFM_Import!$A$5:$A$63,0))=Legacy_Employees!E14,"OK","Mismatch")) -> OK | F14: =IF($C14="No","n/a",IF(INDEX(WFM_Import!$C$5:$C$63,MATCH($A14,WFM_Import!$A$5:$A$63,0))=Legacy_Employees!C14,"OK","Mismatch")) -> OK | G14: =IF($C14="No","n/a",IF(INDEX(WFM_Import!$F$5:$F$63,MATCH($A14,WFM_Import!$A$5:$A$63,0))=Legacy_Employees!F14,"OK","Mismatch")) -> OK | H14: =IF($C14="No","Missing",IF(COUNTIF(D14:G14,"OK")=4,"Match","Mismatch")) -> Match
A15: =Legacy_Employees!A15 -> E1011 | B15: =Legacy_Employees!C15 -> NSW | C15: =IF(ISNUMBER(MATCH($A15,WFM_Import!$A$5:$A$63,0)),"Yes","No") -> Yes | D15: =IF($C15="No","n/a",IF(ROUND(INDEX(WFM_Import!$G$5:$G$63,MATCH($A15,WFM_Import!$A$5:$A$63,0))-Legacy_Employees!G15,2)=0,"OK","Mismatch")) -> OK | E15: =IF($C15="No","n/a",IF(INDEX(WFM_Import!$E$5:$E$63,MATCH($A15,WFM_Import!$A$5:$A$63,0))=Legacy_Employees!E15,"OK","Mismatch")) -> OK | F15: =IF($C15="No","n/a",IF(INDEX(WFM_Import!$C$5:$C$63,MATCH($A15,WFM_Import!$A$5:$A$63,0))=Legacy_Employees!C15,"OK","Mismatch")) -> OK | G15: =IF($C15="No","n/a",IF(INDEX(WFM_Import!$F$5:$F$63,MATCH($A15,WFM_Import!$A$5:$A$63,0))=Legacy_Employees!F15,"OK","Mismatch")) -> OK | H15: =IF($C15="No","Missing",IF(COUNTIF(D15:G15,"OK")=4,"Match","Mismatch")) -> Match
A16: =Legacy_Employees!A16 -> E1012 | B16: =Legacy_Employees!C16 -> NZ | C16: =IF(ISNUMBER(MATCH($A16,WFM_Import!$A$5:$A$63,0)),"Yes","No") -> Yes | D16: =IF($C16="No","n/a",IF(ROUND(INDEX(WFM_Import!$G$5:$G$63,MATCH($A16,WFM_Import!$A$5:$A$63,0))-Legacy_Employees!G16,2)=0,"OK","Mismatch")) -> Mismatch | E16: =IF($C16="No","n/a",IF(INDEX(WFM_Import!$E$5:$E$63,MATCH($A16,WFM_Import!$A$5:$A$63,0))=Legacy_Employees!E16,"OK","Mismatch")) -> OK | F16: =IF($C16="No","n/a",IF(INDEX(WFM_Import!$C$5:$C$63,MATCH($A16,WFM_Import!$A$5:$A$63,0))=Legacy_Employees!C16,"OK","Mismatch")) -> OK | G16: =IF($C16="No","n/a",IF(INDEX(WFM_Import!$F$5:$F$63,MATCH($A16,WFM_Import!$A$5:$A$63,0))=Legacy_Employees!F16,"OK","Mismatch")) -> OK | H16: =IF($C16="No","Missing",IF(COUNTIF(D16:G16,"OK")=4,"Match","Mismatch")) -> Mismatch
... A66: =Legacy_Employees!A66 -> E1023 | B66: =Legacy_Employees!C66 -> QLD | C66: =IF(ISNUMBER(MATCH($A66,WFM_Import!$A$5:$A$63,0)),"Yes","No") -> Yes | D66: =IF($C66="No","n/a",IF(ROUND(INDEX(WFM_Import!$G$5:$G$63,MATCH($A66,WFM_Import!$A$5:$A$63,0))-Legacy_Employees!G66,2)=0,"OK","Mismatch")) -> OK | E66: =IF($C66="No","n/a",IF(INDEX(WFM_Import!$E$5:$E$63,MATCH($A66,WFM_Import!$A$5:$A$63,0))=Legacy_Employees!E66,"OK","Mismatch")) -> OK | F66: =IF($C66="No","n/a",IF(INDEX(WFM_Import!$C$5:$C$63,MATCH($A66,WFM_Import!$A$5:$A$63,0))=Legacy_Employees!C66,"OK","Mismatch")) -> OK | G66: =IF($C66="No","n/a",IF(INDEX(WFM_Import!$F$5:$F$63,MATCH($A66,WFM_Import!$A$5:$A$63,0))=Legacy_Employees!F66,"OK","Mismatch")) -> OK | H66: =IF($C66="No","Missing",IF(COUNTIF(D66:G66,"OK")=4,"Match","Mismatch")) -> Match

Sheet UAT
A1: UAT - test cases and execution log
A2: Execution results are SIMULATED for the portfolio. Change Status via dropdown; Dashboard updates.
A4: Test ID | B4: Req ID | C4: Scenario | D4: Steps | E4: Expected result | F4: Status | G4: Defect ref
A5: T01 | B5: R01 | C5: Mobile clock-in inside depot geofence | D5: 1. Open app 2. Tap Clock In at depot | E5: Clock-in recorded with GPS, status Active | F5: Pass
A6: T02 | B6: R01 | C6: Clock-in outside geofence | D6: 1. Move 2km from depot 2. Tap Clock In | E6: Warning shown, entry flagged for approval | F6: Pass
A7: T03 | B7: R02 | C7: Roster skills match | D7: 1. Build roster for job needing licensed technician | E7: Only qualified staff offered | F7: Pass
A8: T04 | B8: R03 | C8: Overtime beyond 7.6 hrs | D8: 1. Submit 10.5 hr shift for FS-L2 | E8: 2.9 OT hrs @1.5x (worked example on Config sheet) | F8: Pass
A9: T05 | B9: R03 | C9: Weekend penalty rate TL-L4 | D9: 1. Submit Saturday shift for TL-L4 | E9: Rate x1.75 applied | F9: Fail | G9: DEF-004
A10: T06 | B10: R04 | C10: Leave request approval | D10: 1. Employee requests 2 days 2. Leader approves | E10: Balance reduced, roster updated | F10: Pass
A11: T07 | B11: R05 | C11: Dispatch nearest qualified crew | D11: 1. Create urgent job in QLD | E11: Nearest qualified crew suggested | F11: Pass
A12: T08 | B12: R05 | C12: Dispatch with no crew available | D12: 1. Create job outside coverage | E12: Escalation alert raised | F12: Blocked | G12: DEF-007
A13: T09 | B13: R06 | C13: Migrated record count matches | D13: 1. Compare Recon summary | E13: 100% of legacy IDs in WFM | F13: Fail | G13: DEF-001
A14: T10 | B14: R06 | C14: Rates and award codes match | D14: 1. Review Recon mismatches | E14: Zero field mismatches | F14: Fail | G14: DEF-002
A15: T11 | B15: R07 | C15: Timesheet approval before cut-off | D15: 1. Leader approves queue | E15: Approved hours locked | F15: Pass
A16: T12 | B16: R08 | C16: Payroll export file format | D16: 1. Run export 2. Validate against spec | E16: File passes payroll validation | F16: Pass
A17: T13 | B17: R09 | C17: NZ public holiday pay | D17: 1. Submit NZ shift on public holiday | E17: NZ holiday rule applied | F17: Not Run
A18: T14 | B18: R10 | C18: Labour cost report totals | D18: 1. Run weekly report 2. Compare to Excel | E18: Totals agree to the cent | F18: Pass
A19: T15 | B19: R11 | C19: Employee cannot approve own timesheet | D19: 1. Login as team leader 2. Approve own | E19: Action blocked | F19: Pass
A20: T16 | B20: R12 | C20: Audit trail on edit | D20: 1. Edit hours 2. Open audit log | E20: Who/when/old/new value logged | F20: Pass
A21: T17 | B21: R13 | C21: Roster publish performance | D21: 1. Publish 2,300-person roster | E21: Completes < 60 seconds | F21: Not Run

Sheet GoLive_Training
A1: GoLive_Training - cutover checklist and training materials plan
A4: Cutover task | B4: Owner | C4: When | D4: Status
A5: Freeze legacy data changes | B5: Payroll Manager | C5: T-5 days | D5: Done
A6: Run final extract and Validation checks | B6: BA | C6: T-4 days | D6: Done
A7: Load to WFM and run Recon | B7: BA / Vendor | C7: T-3 days | D7: In progress
A8: Resolve Recon mismatches (zero critical) | B8: BA / Vendor | C8: T-2 days | D8: Not started
A9: Go/No-go meeting | B9: Head of Transformation | C9: T-1 day | D9: Not started
A10: Go live and hypercare begins | B10: All | C10: T-0 | D10: Not started
A13: Audience | B13: Training material | C13: Format | D13: Req ID
A14: Employee | B14: Mobile clock-in/out quick card | C14: 1-page PDF | D14: R01
A15: Team Leader | B15: Approve timesheets and exceptions guide | C15: 6-page guide | D15: R07
A16: Depot Admin | B16: Rostering and leave user guide | C16: 10-page guide | D16: R02
A17: Payroll | B17: Award rules and export runbook | C17: 8-page guide | D17: R03
A18: Trainers | B18: Train-the-trainer deck and demo script | C18: Slides | D18: R14

Sheet Resume_Uplift
A1: Resume_Uplift - map each SkillSyncer gap to project evidence
A2: Only use a bullet once you have actually built/done that part. Project is labelled self-directed, matching your existing resume style.
A4: SkillSyncer gap keywords | B4: Project evidence | C4: Suggested resume bullet (edit to match what you did)
A5: Data Migration, Migration, Reconciliation | B5: WFM_Import + Recon sheets | C5: Designed legacy-to-WFM data migration reconciliation across 60+ records, identifying 4 missing records, 5 rate and 3 award mismatches via INDEX/MATCH checks.
A6: Data Validation, Pivot Tables, Reporting Requirements | B6: Validation sheet + Dashboard summary tables | C6: Built pre-migration validation rules (duplicates, invalid codes, out-of-range rates) and pivot-style summaries, giving a go/no-go view of data quality.
A7: Requirements Gathering, System Requirements, Stakeholder Engagement | B7: Requirements (RTM) | C7: Documented 15 prioritised (MoSCoW) requirements across 11 stakeholder groups with traceability to test cases and coverage gap checks.
A8: Process Mapping (current/future state) | B8: Process_Map | C8: Mapped current vs future state timesheet-to-pay process, linking 7 pain points to system requirements.
A9: System Configuration, Support System | B9: Config sheet | C9: Defined award-based pay rule configuration (rates, overtime, weekend multipliers) and validated with a worked overtime test.
A10: Testing, Performance Testing | B10: UAT | C10: Authored 17 UAT cases traced to requirements, logged defects and tracked pass rate (incl. performance test for 2,300 users).
A11: Training Materials, System Implementation, Launch | B11: GoLive_Training | C11: Planned cutover checklist and role-based training materials for go-live and hypercare.
A12: Agile / waterfall | B12: Add yourself | C12: Add a line on Agile ways of working from your Deakin work or internship (e.g. sprint-style backlog, stand-ups) only if true.
A13: Communication, Confidence | B13: Summary | C13: Rework summary to lead with 'stakeholder communication' and system implementation.
